 * Running on http://0.0.0.0:5000/ (Press CTRL+C to quit)
[2019-03-27 16:51:40,080] ERROR in app: Exception on / [GET]
Traceback (most recent call last):
  File "/usr/lib/python3/dist-packages/flask/app.py", line 1982, in wsgi_app
    response = self.full_dispatch_request()
  File "/usr/lib/python3/dist-packages/flask/app.py", line 1614, in full_dispatch_request
    rv = self.handle_user_exception(e)
  File "/usr/lib/python3/dist-packages/flask/app.py", line 1517, in handle_user_exception
    reraise(exc_type, exc_value, tb)
  File "/usr/lib/python3/dist-packages/flask/_compat.py", line 33, in reraise
    raise value
  File "/usr/lib/python3/dist-packages/flask/app.py", line 1612, in full_dispatch_request
    rv = self.dispatch_request()
  File "/usr/lib/python3/dist-packages/flask/app.py", line 1598, in dispatch_request
    return self.view_functions[rule.endpoint](**req.view_args)
  File "./app.py", line 71, in display_content
    norm_turp_std.append(exp["standard_deviation"]["Turp"])
KeyError: 'Turp'
168.122.1.149 - - [27/Mar/2019 16:51:40] "GET / HTTP/1.1" 500 -
168.122.1.149 - - [27/Mar/2019 16:51:40] "GET /favicon.ico HTTP/1.1" 404 -
[2019-03-27 16:52:07,607] ERROR in app: Exception on / [GET]
Traceback (most recent call last):
  File "/usr/lib/python3/dist-packages/flask/app.py", line 1982, in wsgi_app
    response = self.full_dispatch_request()
  File "/usr/lib/python3/dist-packages/flask/app.py", line 1614, in full_dispatch_request
    rv = self.handle_user_exception(e)
  File "/usr/lib/python3/dist-packages/flask/app.py", line 1517, in handle_user_exception
    reraise(exc_type, exc_value, tb)
  File "/usr/lib/python3/dist-packages/flask/_compat.py", line 33, in reraise
    raise value
  File "/usr/lib/python3/dist-packages/flask/app.py", line 1612, in full_dispatch_request
    rv = self.dispatch_request()
  File "/usr/lib/python3/dist-packages/flask/app.py", line 1598, in dispatch_request
    return self.view_functions[rule.endpoint](**req.view_args)
  File "./app.py", line 71, in display_content
    norm_turp_std.append(exp["standard_deviation"]["Turp"])
KeyError: 'Turp'
168.122.1.149 - - [27/Mar/2019 16:52:07] "GET / HTTP/1.1" 500 -
[2019-03-27 16:55:00,405] ERROR in app: Exception on / [GET]
Traceback (most recent call last):
  File "/usr/lib/python3/dist-packages/flask/app.py", line 1982, in wsgi_app
    response = self.full_dispatch_request()
  File "/usr/lib/python3/dist-packages/flask/app.py", line 1614, in full_dispatch_request
    rv = self.handle_user_exception(e)
  File "/usr/lib/python3/dist-packages/flask/app.py", line 1517, in handle_user_exception
    reraise(exc_type, exc_value, tb)
  File "/usr/lib/python3/dist-packages/flask/_compat.py", line 33, in reraise
    raise value
  File "/usr/lib/python3/dist-packages/flask/app.py", line 1612, in full_dispatch_request
    rv = self.dispatch_request()
  File "/usr/lib/python3/dist-packages/flask/app.py", line 1598, in dispatch_request
    return self.view_functions[rule.endpoint](**req.view_args)
  File "./app.py", line 71, in display_content
    norm_turp_std.append(exp["standard_deviation"]["Turp"])
KeyError: 'Turp'
168.122.1.149 - - [27/Mar/2019 16:55:00] "GET / HTTP/1.1" 500 -
[2019-03-27 16:59:32,107] ERROR in app: Exception on / [GET]
Traceback (most recent call last):
  File "/usr/lib/python3/dist-packages/flask/app.py", line 1982, in wsgi_app
    response = self.full_dispatch_request()
  File "/usr/lib/python3/dist-packages/flask/app.py", line 1614, in full_dispatch_request
    rv = self.handle_user_exception(e)
  File "/usr/lib/python3/dist-packages/flask/app.py", line 1517, in handle_user_exception
    reraise(exc_type, exc_value, tb)
  File "/usr/lib/python3/dist-packages/flask/_compat.py", line 33, in reraise
    raise value
  File "/usr/lib/python3/dist-packages/flask/app.py", line 1612, in full_dispatch_request
    rv = self.dispatch_request()
  File "/usr/lib/python3/dist-packages/flask/app.py", line 1598, in dispatch_request
    return self.view_functions[rule.endpoint](**req.view_args)
  File "./app.py", line 67, in display_content
    norm_ph_std.append(exp["standard_deviation"]["PH"])
KeyError: 'PH'
168.122.1.149 - - [27/Mar/2019 16:59:32] "GET / HTTP/1.1" 500 -
[2019-03-27 17:04:15,229] ERROR in app: Exception on / [GET]
Traceback (most recent call last):
  File "/usr/lib/python3/dist-packages/flask/app.py", line 1982, in wsgi_app
    response = self.full_dispatch_request()
  File "/usr/lib/python3/dist-packages/flask/app.py", line 1614, in full_dispatch_request
    rv = self.handle_user_exception(e)
  File "/usr/lib/python3/dist-packages/flask/app.py", line 1517, in handle_user_exception
    reraise(exc_type, exc_value, tb)
  File "/usr/lib/python3/dist-packages/flask/_compat.py", line 33, in reraise
    raise value
  File "/usr/lib/python3/dist-packages/flask/app.py", line 1612, in full_dispatch_request
    rv = self.dispatch_request()
  File "/usr/lib/python3/dist-packages/flask/app.py", line 1598, in dispatch_request
    return self.view_functions[rule.endpoint](**req.view_args)
  File "./app.py", line 67, in display_content
    norm_ph_std.append(exp["standard_deviation"]["PH"])
KeyError: 'PH'
168.122.1.149 - - [27/Mar/2019 17:04:15] "GET / HTTP/1.1" 500 -
[2019-03-27 17:05:17,695] ERROR in app: Exception on / [GET]
Traceback (most recent call last):
  File "/usr/lib/python3/dist-packages/flask/app.py", line 1982, in wsgi_app
    response = self.full_dispatch_request()
  File "/usr/lib/python3/dist-packages/flask/app.py", line 1614, in full_dispatch_request
    rv = self.handle_user_exception(e)
  File "/usr/lib/python3/dist-packages/flask/app.py", line 1517, in handle_user_exception
    reraise(exc_type, exc_value, tb)
  File "/usr/lib/python3/dist-packages/flask/_compat.py", line 33, in reraise
    raise value
  File "/usr/lib/python3/dist-packages/flask/app.py", line 1612, in full_dispatch_request
    rv = self.dispatch_request()
  File "/usr/lib/python3/dist-packages/flask/app.py", line 1598, in dispatch_request
    return self.view_functions[rule.endpoint](**req.view_args)
  File "./app.py", line 67, in display_content
    #         norm_ph_std.append(exp["standard_deviation"]["PH"])
KeyError: 'PH'
168.122.1.149 - - [27/Mar/2019 17:05:17] "GET / HTTP/1.1" 500 -
[2019-03-27 17:06:37,526] ERROR in app: Exception on / [GET]
Traceback (most recent call last):
  File "/usr/lib/python3/dist-packages/flask/app.py", line 1982, in wsgi_app
    response = self.full_dispatch_request()
  File "/usr/lib/python3/dist-packages/flask/app.py", line 1614, in full_dispatch_request
    rv = self.handle_user_exception(e)
  File "/usr/lib/python3/dist-packages/flask/app.py", line 1517, in handle_user_exception
    reraise(exc_type, exc_value, tb)
  File "/usr/lib/python3/dist-packages/flask/_compat.py", line 33, in reraise
    raise value
  File "/usr/lib/python3/dist-packages/flask/app.py", line 1612, in full_dispatch_request
    rv = self.dispatch_request()
  File "/usr/lib/python3/dist-packages/flask/app.py", line 1598, in dispatch_request
    return self.view_functions[rule.endpoint](**req.view_args)
  File "./app.py", line 67, in display_content
KeyError: 'PH'
168.122.1.149 - - [27/Mar/2019 17:06:37] "GET / HTTP/1.1" 500 -
[2019-03-27 17:08:49,791] ERROR in app: Exception on / [GET]
Traceback (most recent call last):
  File "/usr/lib/python3/dist-packages/flask/app.py", line 1982, in wsgi_app
    response = self.full_dispatch_request()
  File "/usr/lib/python3/dist-packages/flask/app.py", line 1614, in full_dispatch_request
    rv = self.handle_user_exception(e)
  File "/usr/lib/python3/dist-packages/flask/app.py", line 1517, in handle_user_exception
    reraise(exc_type, exc_value, tb)
  File "/usr/lib/python3/dist-packages/flask/_compat.py", line 33, in reraise
    raise value
  File "/usr/lib/python3/dist-packages/flask/app.py", line 1612, in full_dispatch_request
    rv = self.dispatch_request()
  File "/usr/lib/python3/dist-packages/flask/app.py", line 1598, in dispatch_request
    return self.view_functions[rule.endpoint](**req.view_args)
  File "./app.py", line 67, in display_content
KeyError: 'PH'
168.122.1.149 - - [27/Mar/2019 17:08:49] "GET / HTTP/1.1" 500 -
[2019-03-27 17:10:37,226] ERROR in app: Exception on / [GET]
Traceback (most recent call last):
  File "/usr/lib/python3/dist-packages/flask/app.py", line 1982, in wsgi_app
    response = self.full_dispatch_request()
  File "/usr/lib/python3/dist-packages/flask/app.py", line 1614, in full_dispatch_request
    rv = self.handle_user_exception(e)
  File "/usr/lib/python3/dist-packages/flask/app.py", line 1517, in handle_user_exception
    reraise(exc_type, exc_value, tb)
  File "/usr/lib/python3/dist-packages/flask/_compat.py", line 33, in reraise
    raise value
  File "/usr/lib/python3/dist-packages/flask/app.py", line 1612, in full_dispatch_request
    rv = self.dispatch_request()
  File "/usr/lib/python3/dist-packages/flask/app.py", line 1598, in dispatch_request
    return self.view_functions[rule.endpoint](**req.view_args)
  File "./app.py", line 67, in display_content
KeyError: 'PH'
168.122.1.149 - - [27/Mar/2019 17:10:37] "GET / HTTP/1.1" 500 -
Traceback (most recent call last):
  File "./app.py", line 81, in <module>
    app.run(host= '0.0.0.0')
  File "/usr/lib/python3/dist-packages/flask/app.py", line 841, in run
    run_simple(host, port, self, **options)
  File "/usr/lib/python3/dist-packages/werkzeug/serving.py", line 708, in run_simple
    inner()
  File "/usr/lib/python3/dist-packages/werkzeug/serving.py", line 670, in inner
    fd=fd)
  File "/usr/lib/python3/dist-packages/werkzeug/serving.py", line 564, in make_server
    passthrough_errors, ssl_context, fd=fd)
  File "/usr/lib/python3/dist-packages/werkzeug/serving.py", line 476, in __init__
    HTTPServer.__init__(self, (host, int(port)), handler)
  File "/usr/lib/python3.5/socketserver.py", line 440, in __init__
    self.server_bind()
  File "/usr/lib/python3.5/http/server.py", line 138, in server_bind
    socketserver.TCPServer.server_bind(self)
  File "/usr/lib/python3.5/socketserver.py", line 454, in server_bind
    self.socket.bind(self.server_address)
OSError: [Errno 98] Address already in use
[2019-03-27 17:12:36,938] ERROR in app: Exception on / [GET]
Traceback (most recent call last):
  File "/usr/lib/python3/dist-packages/flask/app.py", line 1982, in wsgi_app
    response = self.full_dispatch_request()
  File "/usr/lib/python3/dist-packages/flask/app.py", line 1614, in full_dispatch_request
    rv = self.handle_user_exception(e)
  File "/usr/lib/python3/dist-packages/flask/app.py", line 1517, in handle_user_exception
    reraise(exc_type, exc_value, tb)
  File "/usr/lib/python3/dist-packages/flask/_compat.py", line 33, in reraise
    raise value
  File "/usr/lib/python3/dist-packages/flask/app.py", line 1612, in full_dispatch_request
    rv = self.dispatch_request()
  File "/usr/lib/python3/dist-packages/flask/app.py", line 1598, in dispatch_request
    return self.view_functions[rule.endpoint](**req.view_args)
  File "./app.py", line 67, in display_content
KeyError: 'PH'
168.122.1.149 - - [27/Mar/2019 17:12:36] "GET / HTTP/1.1" 500 -
 * Running on http://0.0.0.0:5000/ (Press CTRL+C to quit)
[2019-03-27 17:13:12,703] ERROR in app: Exception on / [GET]
Traceback (most recent call last):
  File "/usr/lib/python3/dist-packages/flask/app.py", line 1982, in wsgi_app
    response = self.full_dispatch_request()
  File "/usr/lib/python3/dist-packages/flask/app.py", line 1614, in full_dispatch_request
    rv = self.handle_user_exception(e)
  File "/usr/lib/python3/dist-packages/flask/app.py", line 1517, in handle_user_exception
    reraise(exc_type, exc_value, tb)
  File "/usr/lib/python3/dist-packages/flask/_compat.py", line 33, in reraise
    raise value
  File "/usr/lib/python3/dist-packages/flask/app.py", line 1612, in full_dispatch_request
    rv = self.dispatch_request()
  File "/usr/lib/python3/dist-packages/flask/app.py", line 1598, in dispatch_request
    return self.view_functions[rule.endpoint](**req.view_args)
  File "./app.py", line 28, in display_content
    contaminated_norm = norm_df[norm_df.Contaminated >= 1]
NameError: name 'norm_df' is not defined
168.122.1.149 - - [27/Mar/2019 17:13:12] "GET / HTTP/1.1" 500 -
[2019-03-27 17:13:28,839] ERROR in app: Exception on / [GET]
Traceback (most recent call last):
  File "/usr/lib/python3/dist-packages/flask/app.py", line 1982, in wsgi_app
    response = self.full_dispatch_request()
  File "/usr/lib/python3/dist-packages/flask/app.py", line 1614, in full_dispatch_request
    rv = self.handle_user_exception(e)
  File "/usr/lib/python3/dist-packages/flask/app.py", line 1517, in handle_user_exception
    reraise(exc_type, exc_value, tb)
  File "/usr/lib/python3/dist-packages/flask/_compat.py", line 33, in reraise
    raise value
  File "/usr/lib/python3/dist-packages/flask/app.py", line 1612, in full_dispatch_request
    rv = self.dispatch_request()
  File "/usr/lib/python3/dist-packages/flask/app.py", line 1598, in dispatch_request
    return self.view_functions[rule.endpoint](**req.view_args)
  File "./app.py", line 28, in display_content
    contaminated_norm = norm_df[norm_df.Contaminated >= 1]
NameError: name 'norm_df' is not defined
168.122.1.149 - - [27/Mar/2019 17:13:28] "GET / HTTP/1.1" 500 -
 * Running on http://0.0.0.0:5000/ (Press CTRL+C to quit)
168.122.1.149 - - [27/Mar/2019 17:14:11] "GET / HTTP/1.1" 200 -
168.122.1.149 - - [27/Mar/2019 17:14:27] "GET / HTTP/1.1" 200 -
